Workbook

Sheet Eingabe
A1: Vorkette
A2: Vorkettenemissionsfaktor Erdgas gCO₂eq/kWh CH4 | B2: 27
A3: Vorkettenenergiebedarf Erdgas | B3: 0.08
A5: Reaktion
A6: Masse CH4 in kg | B6: 1
A7: Umsatzgrad SMR | B7: 0.9
A8: Umsatzgrad WGS | B8: 0.99
A9: Wasserüberschuss | B9: 3
A10: T_raum in °C | B10: 25
A11: T_dampf in °C | B11: 100
A12: T_entschwefelung in °C | B12: 350
A13: T_reaktion in °C | B13: 850
A15: Energysupply
A16: recovery rate | B16: 0.85
A17: PSA energieverbrauch in kwh/ton H2 | B17: 400
A19: CO2-Abstoß Faktor
A20: Faktor CH4-Feuerung in gCO2/kgCH4 | B20: =44/16*1000 -> 2750
A21: Faktor Strommix gCO2eq/kwh | B21: 353
A22: Faktor Zukunftsstrom gCO2eq/kwh | B22: 33

Sheet Vorkette
A1: =Eingabe!A2 -> Vorkettenemissionsfaktor Erdgas gCO₂eq/kWh CH4 | B1: =Eingabe!B2 -> 27
A2: =Eingabe!A3 -> Vorkettenenergiebedarf Erdgas | B2: =Eingabe!B3 -> 0.08
A6: scenario | B6: Stromheizung | C6: Erdgasfeuerung
A7: CH4-Rohstoff in kg/kg H2 | B7: =1/'PSA+Verdichten'!B5 -> 2.6209314 | C7: =B7 -> 2.6209314
A8: CH4-Rohstoff in kwh/kwh H2 | B8: =B7/'SMR+WGS'!N46*'SMR+WGS'!N47 -> 1.0920548 | C8: =B8 -> 1.0920548
A9: CH4 für Prozesswärme in kwh/kwh H2 | B9: =0 -> 0 | C9: ='SMR+WGS'!M42 -> 0.40008087
A10: CH4 gesamt in kwh/kwh H2 | B10: =B8+B9 -> 1.0920548 | C10: =C8+C9 -> 1.4921356
A11: Vorketten-CO2 | B11: =B10*B1 -> 29.485478 | C11: =C10*B1 -> 40.287662
A12: Vorkettenenergie kwh/kwh H2 | B12: =B10*B2 -> 0.08736438 | C12: =C10*B2 -> 0.11937085

Sheet SMR+WGS
A1: Stoffbilanz | L1: Energiebilanz
A2: reine reaktionsgleichung | L2: Reaktionsenthalpie(Trkt):
B3: stöchiometrisch | C3: Masse kg | D3: Molare Masse g/mol | E3: Stoffmenge mol | M3: °C | N3: K/1000
A4: CH4 | B4: 1 | C4: 1 | D4: 16 | E4: =(C4*1000)/16 -> 62.5 | L4: T_raum | M4: =Eingabe!B10 -> 25 | N4: =(M4+273.15)/1000 -> 0.29815
A5: H2O | B5: 2 | C5: =(E5*D5)/1000 -> 2.25 | D5: 18 | E5: =B5*E4 -> 125 | L5: T_dampf | M5: =Eingabe!B11 -> 100 | N5: =(M5+273.15)/1000 -> 0.37315
A6: CO2 | B6: 1 | C6: =(E6*D6)/1000 -> 2.75 | D6: 44 | E6: =B6*E4 -> 62.5 | L6: T_entschwefelung | M6: =Eingabe!B12 -> 350 | N6: =(M6+273.15)/1000 -> 0.62315
A7: H2 | B7: 4 | C7: =(E7*D7)/1000 -> 0.5 | D7: 2 | E7: =B7*E4 -> 250 | L7: T_reaktion | M7: =Eingabe!B13 -> 850 | N7: =(M7+273.15)/1000 -> 1.12315
L9: Gas Phase Heat Capacity (Shomate Equation)
M10: CH4 | N10: H2O | O10: CO2 | P10: H2 | Q10: CO
A11: Realität | L11: A | M11: -0.703029 | N11: 30.092 | O11: =24.99735 -> 24.99735 | P11: 18.563083 | Q11: 25.56759
B12: Einsatzmasse kg | C12: Molare Masse g/mol | D12: Einsatzstoffmenge mol | E12: Überschuss/Umsatz | F12: stöchiometrisch | G12: Stoffmenge beteiligt mol | H12: Stoffmengeübrig mol | I12: Masse übrig/produziert kg | L12: B | M12: 108.4773 | N12: 6.832514 | O12: =55.18696 -> 55.18696 | P12: 12.257357 | Q12: 6.09613
A13: CH4 | B13: =Eingabe!B6 -> 1 | C13: 16 | D13: =B13*1000/C13 -> 62.5 | E13: =Eingabe!B7 -> 0.9 | F13: 1 | G13: =D13*E13 -> 56.25 | H13: =D13-G13 -> 6.25 | I13: =H13*C13/1000 -> 0.1 | L13: C | M13: -42.52157 | N13: 6.793435 | O13: -33.69137 | P13: -2.859786 | Q13: 4.054656
A14: H2O | B14: =D14*C14/1000 -> 3.375 | C14: 18 | D14: =D13*E14 -> 187.5 | E14: =Eingabe!B9 -> 3 | F14: 2 | G14: =F13*G13+F15*G15 -> 111.9375 | H14: =D14-G14 -> 75.5625 | I14: =H14*C14/1000 -> 1.360125 | L14: D | M14: 5.862788 | N14: -2.53448 | O14: 7.948387 | P14: 0.268238 | Q14: -2.671301
A15: CO | C15: 28 | E15: =Eingabe!B8 -> 0.99 | F15: 1 | G15: =G13*E15 -> 55.6875 | H15: =G13-G15 -> 0.5625 | I15: =H15*C15/1000 -> 0.01575 | L15: E | M15: 0.678565 | N15: 0.082139 | O15: -0.136638 | P15: 1.97799 | Q15: 0.131021
A16: CO2 | C16: 44 | F16: 1 | G16: =G15 -> 55.6875 | I16: =G16*C16/1000 -> 2.45025 | L16: F | M16: =-76.84376 -> -76.84376 | N16: =-250.881 -> -250.881 | O16: -403.6075 | P16: -1.147438 | Q16: -118.0089
A17: H2 | C17: 2 | F17: 4 | G17: =G13*3+G15*1 -> 224.4375 | I17: =G17*C17/1000 -> 0.448875 | L17: H | M17: =-74.8731 -> -74.8731 | N17: =-241.8264 -> -241.8264 | O17: -393.5224 | P17: 0 | Q17: -110.5271
L19: Enthalpie
M20: H_rel(T_reaktion) | N20: ΔHf(298K) | O20: h(T_reaktion)
L21: CH4 | M21: =M11*N7+M12*N7^2/2+M13*N7^3/3+M14*N7^4/4-M15/N7+M16-M17 -> 47.306398 | N21: =M17 -> -74.8731 | O21: =M21+N21 -> -27.566702
L22: H2O | M22: =N11*N7+N12*N7^2/2+N13*N7^3/3+N14*N7^4/4-N15/N7+N16-N17 -> 31.17966 | N22: =N17 -> -241.8264 | O22: =M22+N22 -> -210.64674
L23: CO2 | M23: =O11*N7+O12*N7^2/2+O13*N7^3/3+O14*N7^4/4-O15/N7+O16-O17 -> 40.17114 | N23: =O17 -> -393.5224 | O23: =M23+N23 -> -353.35126
L24: H2 | M24: =P11*N7+P12*N7^2/2+P13*N7^3/3+P14*N7^4/4-P15/N7+P16-P17 -> 24.427814 | N24: =P17 -> 0 | O24: =M24+N24 -> 24.427814
L25: CO | M25: =Q11*N7+Q12*N7^2/2+Q13*N7^3/3+Q14*N7^4/4-Q15/N7+Q16-Q17 -> 25.815006 | N25: =Q17 -> -110.5271 | O25: =M25+N25 -> -84.712094
L27: Reaktionsenthalpie
L28: ΔH_SMR bei 850°C | M28: =O25+3*O24-O21-O22 -> 226.78479
L29: ΔH_WGS bei 850°C | M29: =O23+O24-O25-O22 -> -33.564612
L30: Q_Reaktion | M30: =Eingabe!B7*M28+Eingabe!B7*Eingabe!B8*M29 -> 174.20024
L32: Aufheizenergie in kj/mol
L33: Stoff | M33: T_ein °C | N33: T_reaktion °C | O33: H_rel(T_ein) | P33: H_rel(T_reaktion) | Q33: q_i | R33: n_i_promolCH4 | S33: Q_i
L34: CH4 | M34: =M6 -> 350 | N34: =M7 -> 850 | O34: =M11*N6+M12*N6^2/2+M13*N6^3/3+M14*N6^4/4-M15/N6+M16-M17 -> 14.355286 | P34: =M21 -> 47.306398 | Q34: =P34-O34 -> 32.951112 | R34: =1 -> 1 | S34: =R34*Q34 -> 32.951112
L35: H2O | M35: =M5 -> 100 | N35: =M7 -> 850 | O35: =N11*N5+N12*N5^2/2+N13*N5^3/3+N14*N5^4/4-N15/N5+N16-N17 -> 2.5351619 | P35: =M22 -> 31.17966 | Q35: =P35-O35 -> 28.644498 | R35: =3 -> 3 | S35: =R35*Q35 -> 85.933493
L36: Summe | S36: =S34+S35 -> 118.88461
L38: Reaktionsenthalpie kj/mol | M38: =M30 -> 174.20024
L39: Qaufheiz insgesamt kj/mol ch4 | M39: =S36 -> 118.88461
L40: Prozesswärmebedarf in kj/mol | M40: =M38+M39 -> 293.08485
L41: Prozesswärmebedarf in kwh/kg CH4 | M41: =M40*D13/1000/3.6 -> 5.0882786
L42: Prozesswärmebedarf in kwh/kwh H2 | M42: =M41/'PSA+Verdichten'!B5/'SMR+WGS'!N46 -> 0.40008087
L44: chemische Energie:
M45: Heizwert MJ/kg | N45: Heizwert kwh/kg
L46: H2 | M46: 120 | N46: =M46/3.6 -> 33.333333
...

Sheet PSA+Verdichten
A1: Stoffbilanz | F1: Energiebilanz
A2: recovery rate | B2: =Eingabe!B16 -> 0.85 | F2: Strombedarf PSA
A3: H2 vor PSA kg | B3: ='SMR+WGS'!I17 -> 0.448875 | F3: Strombedarf PSA kwh/ton H2 | G3: =Eingabe!B17 -> 400
A4: H2 vor PSA mol | B4: =B3*1000/'SMR+WGS'!D7 -> 224.4375 | F4: Strombedarf PSA kwh/ kwhH2 | G4: =G3/1000/'SMR+WGS'!N46 -> 0.012
A5: H2 nach PSA kg | B5: =B3*B2 -> 0.38154375
A6: H2 nach PSA mol | B6: =B5*1000/'SMR+WGS'!D7 -> 190.77187 | F6: Energie verdichten
G7: CH4 verdichten | H7: H2 produkt verdichten
F8: Stoffmenge mol | G8: ='SMR+WGS'!D13 -> 62.5 | H8: =B6 -> 190.77187
F9: Gaskonstante J/mol*K | G9: 8.314 | H9: 8.314
F10: Temperatur K | G10: ='SMR+WGS'!M6+273.15 -> 623.15 | H10: ='SMR+WGS'!M4+273.15 -> 298.15
F11: p0 bar | G11: 1 | H11: 35
F12: p1 bar | G12: 30 | H12: 80
F13: Verdichtungsenergie kJ | G13: =G8*G9*G10*LN(G12/G11)/1000 -> 1101.3224 | H13: =H8*H9*H10*LN(H12/H11)/1000 -> 390.92718
F14: Verdichtungsenergie kwh | G14: =G13*10^-3/3.6 -> 0.30592289 | H14: =H13*10^-3/3.6 -> 0.10859088
F15: Verdichtungsenergie kwh/kwhH2 | G15: =G14/B5/'SMR+WGS'!N46 -> 0.024054087 | H15: =H14/B5/'SMR+WGS'!N46 -> 0.0085382777
F16: Verdichtungsenergiegesamt kwh/kwhH2 | G16: =G15+H15 -> 0.032592365
F18: Strombedarf PSA+Verdichtung kwh/kwh H2 | G18: =G4+G16 -> 0.044592365

Sheet Ergebnis
A1: Energiebilanz (kwh/kwh H2) | E1: CO2-Bilanz gCO2eq/kwh H2
B2: Erdgas-Feuerung | C2: Stromheizung | F2: Erdgasfeuerung+Strommix2024 | G2: Erdgasfeuerung+Zukunftsstrom | H2: Stromheizung Strommix 2024 | I2: Stromheizung Zukunftsstrom
A3: Vorkettenenergie | B3: =Vorkette!C12 -> 0.11937085 | C3: =Vorkette!B12 -> 0.08736438 | E3: Vorkette | F3: =B42 -> 40.287662 | G3: =E42 -> 40.287662 | H3: =H42 -> 29.485478 | I3: =K42 -> 29.485478
A4: Rohstoffenergie+Prozesswärmebedarf | B4: ='SMR+WGS'!M53 -> 1.4921356 | C4: ='SMR+WGS'!M53 -> 1.4921356 | E4: Prozess-CO2 | F4: =B46 -> 192.65812 | G4: =E46 -> 192.65812 | H4: =H46 -> 192.65812 | I4: =K46 -> 192.65812
A5: Strombedarf PSA+Verdichtung | B5: ='PSA+Verdichten'!G18 -> 0.044592365 | C5: ='PSA+Verdichten'!G18 -> 0.044592365 | E5: Energieversorgung | F5: =B57 -> 94.957118 | G5: =E57 -> 80.687561 | H5: =H55 -> 156.96965 | I5: =K55 -> 14.674217
A6: Gesamtenergieeinsatz kwh/kwh H2 | B6: =SUM(B3:B5) -> 1.6560988 | C6: =SUM(C3:C5) -> 1.6240924 | E6: Gesamt CO2 | F6: =B60 -> 327.9029 | G6: =E60 -> 313.63334 | H6: =H60 -> 379.11325 | I6: =K60 -> 236.81781
A7: Wirkungsgrad | B7: =(1/B6) -> 0.60382869 | C7: =1/C6 -> 0.61572852
A39: Detalierter Rechenweg für CO2 Bilanz:
A40: Erdgasfeuerung + Strommix 2024 | D40: Erdgasfeuerung + Zukunftsstrom | G40: Stromheizung Strommix 2024 | J40: Stromheizung Zukunftsstrom
A41: =E3 -> Vorkette | D41: =A41 -> Vorkette | G41: =A41 -> Vorkette | J41: =A41 -> Vorkette
A42: CO2 Emissionen in g/kwh H2 | B42: =Vorkette!C11 -> 40.287662 | D42: CO2 Emissionen in g/kwh H2 | E42: =B42 -> 40.287662 | G42: CO2 Emissionen in g/kwh H2 | H42: =Vorkette!B11 -> 29.485478 | J42: CO2 Emissionen in g/kwh H2 | K42: =H42 -> 29.485478
A44: =E4 -> Prozess-CO2 | D44: =A44 -> Prozess-CO2 | G44: =A44 -> Prozess-CO2 | J44: =A44 -> Prozess-CO2
A45: CO2 Emissionen durch reaktion in kg CO2/kg H2 | B45: ='SMR+WGS'!I16/'PSA+Verdichten'!B5 -> 6.4219372 | D45: CO2 Emissionen durch reaktion in kg CO2/kg H2 | E45: ='SMR+WGS'!I16/'PSA+Verdichten'!B5 -> 6.4219372 | G45: CO2 Emissionen durch reaktion in kg CO2/kg H2 | H45: ='SMR+WGS'!I16/'PSA+Verdichten'!B5 -> 6.4219372 | J45: CO2 Emissionen durch reaktion in kg CO2/kg H2 | K45: ='SMR+WGS'!I16/'PSA+Verdichten'!B5 -> 6.4219372
A46: CO2 Emissionen in g CO2/kwh H2 | B46: =B45*1000/'SMR+WGS'!N46 -> 192.65812 | D46: CO2 Emissionen in g CO2/kwh H2 | E46: =B46 -> 192.65812 | G46: CO2 Emissionen in g CO2/kwh H2 | H46: =H45*1000/'SMR+WGS'!N46 -> 192.65812 | J46: CO2 Emissionen in g CO2/kwh H2 | K46: =K45*1000/'SMR+WGS'!N46 -> 192.65812
A48: =E5 -> Energieversorgung | D48: =A48 -> Energieversorgung | G48: =D48 -> Energieversorgung | J48: =G48 -> Energieversorgung
A49: Prozesswärmebedarf in kwh/kwh H2 | B49: ='SMR+WGS'!M42 -> 0.40008087 | D49: Prozesswärmebedarf in kwh/kwh H2 | E49: ='SMR+WGS'!M42 -> 0.40008087 | G49: Prozesswärmebedarf in kwh/kwh H2 | H49: ='SMR+WGS'!M42 -> 0.40008087 | J49: Prozesswärmebedarf in kwh/kwh H2 | K49: ='SMR+WGS'!M42 -> 0.40008087
A50: Wärmequelle | B50: Erdgasfeuerung | D50: Wärmequelle | E50: Erdgasfeuerung | G50: Wärmequelle | H50: Stromheizung | J50: Wärmequelle | K50: Stromheizung
A51: CH4 Brennstoffbedarf für in kg/kwh H2 | B51: =Ergebnis!B49/'SMR+WGS'!N47 -> 0.028805823 | D51: CH4 Brennstoffbedarf für in kg/kwh H2 | E51: =Ergebnis!B49/'SMR+WGS'!N47 -> 0.028805823 | G51: Strombedarf Prozesswärme kwh/kwh H2 | H51: =H49 -> 0.40008087 | J51: Strombedarf Prozesswärme kwh/kwh H2 | K51: =K49 -> 0.40008087
A52: Faktor CH4-Feuerung, gCO2/kg_CH4 | B52: =Eingabe!B20 -> 2750 | D52: Faktor CH4-Feuerung, gCO2/kg_CH4 | E52: =Eingabe!B20 -> 2750 | G52: Strombedarf PSA+Verdichtung kwh/kwh H2 | H52: ='PSA+Verdichten'!G18 -> 0.044592365 | J52: Strombedarf PSA+Verdichtung kwh/kwh H2 | K52: ='PSA+Verdichten'!G18 -> 0.044592365
A53: CO2 aus CH4-Feuerung in g/kwh H2 | B53: =B51*B52 -> 79.216013 | D53: CO2 aus CH4-Feuerung in g/kwh H2 | E53: =E51*E52 -> 79.216013 | G53: Strombedarf gesamt kwh/kwh H2 | H53: =H51+H52 -> 0.44467324 | J53: Strombedarf gesamt kwh/kwh H2 | K53: =K51+K52 -> 0.44467324
A54: Strombedarf PSA+Verdichtung kwh/kwh H2 | B54: ='PSA+Verdichten'!G18 -> 0.044592365 | D54: Strombedarf PSA+Verdichtung kwh/kwh H2 | E54: ='PSA+Verdichten'!G18 -> 0.044592365 | G54: Faktor Strommix g/kwh | H54: =Eingabe!B21 -> 353 | J54: Faktor Zukunftsstrom g/kwh | K54: =Eingabe!B22 -> 33
A55: Faktor Strommix g/kwh | B55: =Eingabe!B21 -> 353 | D55: Faktor Strommix g/kwh | E55: =Eingabe!B22 -> 33 | G55: CO2 aus Strom gCO2eq/kwhH2 | H55: =H53*H54 -> 156.96965 | J55: CO2 aus Strom gCO2eq/kwhH2 | K55: =K53*K54 -> 14.674217
A56: CO2 emmision Strommix in g/kwh H2 | B56: =B54*Eingabe!B21 -> 15.741105 | D56: CO2 emmision Strommix in g/kwh H2 | E56: =E54*E55 -> 1.471548
A57: energy supply CO2 emmision in g/kwh H2 | B57: =B53+B56 -> 94.957118 | D57: energy supply CO2 emmision in g/kwh H2 | E57: =E53+E56 -> 80.687561
A59: Gesamt | D59: Gesamt | G59: Gesamt | J59: Gesamt
A60: Gesamtemissionen, gCO2e/kWh_H2 | B60: =B42+B46+B57 -> 327.9029 | D60: Gesamtemissionen, gCO2e/kWh_H2 | E60: =E42+E46+E57 -> 313.63334 | G60: Gesamtemissionen, gCO2e/kWh_H2 | H60: =H42+H46+H55 -> 379.11325 | J60: Gesamtemissionen, gCO2e/kWh_H2 | K60: =K42+K46+K55 -> 236.81781
